<robot name="poppy">
  <!-- Base link -->

  <link name="base_link">
    <visual>
      <origin xyz="0 0 .3" rpy="0 0 0" />
      <geometry>
        <box size=".39 .42 .54"/>
      </geometry>
      <material name="orange">
        <color rgba="1. .55 0. .8"/>
      </material>
    </visual>
    <collision>
      <geometry>
        <box size=".39 .42 .54"/>
      </geometry>
    </collision>
  </link>


  <!-- dummy link to add inertia to base_link-->
  <link name="dummy_link">
    <visual>
      <origin xyz="0 0 0.01" rpy="0 0 0" />
      <geometry>
        <box size=".01 .01 .01"/>
      </geometry>
      <material name="orange">
        <color rgba="1. .55 0. .8"/>
      </material>
    </visual>
  </link>


  <joint name="dummy" type="fixed">
    <parent link="base_link"/>
    <child link="dummy_link"/>
    <origin xyz="0 0 0"/>
    <inertial>
      <mass value="5.0"/>
    </inertial>
  </joint>


  <joint name="base_link_to_left_cover" type="fixed">
    <parent link="base_link"/>
    <child link="left_cover"/>
    <origin xyz="0 -0.205 0.775"/>
  </joint>


  <joint name="base_link_to_right_cover" type="fixed">
    <parent link="base_link"/>
    <child link="right_cover"/>
    <origin xyz="0 0.205 0.775"/>
  </joint>


  <joint name="base_link_to_back_cover" type="fixed">
    <parent link="base_link"/>
    <child link="back_cover"/>
    <origin xyz="-0.1945 0 0.775"/>
  </joint>


  <joint name="back_cover_to_top_cover" type="fixed">
    <parent link="back_cover"/>
    <child link="top_cover"/>
    <origin xyz="0.195 0 0.21"/>
  </joint>



  <link name="left_cover">
    <visual>
      <geometry>
        <box size=".39 .01 .41"/>
      </geometry>
      <material name="orange">
        <color rgba="1. .55 0. .8"/>
      </material>
    </visual>
    <collision>
      <geometry>
        <box size=".39 .01 .41"/>
      </geometry>
    </collision>
    <inertial>
      <inertia ixx="1e-3" ixy="0.0" ixz="0.0" iyy="1e-3" iyz="0.0" izz="1e-3"/>
      <mass value=".1"/>
    </inertial>
  </link>


  <link name="right_cover">
    <visual>
      <geometry>
        <box size=".39 .01 .41"/>
      </geometry>
      <material name="orange">
        <color rgba="1. .55 0. .8"/>
      </material>
    </visual>
    <collision>
      <geometry>
        <box size=".39 .01 .41"/>
      </geometry>
    </collision>
    <inertial>
      <inertia ixx="1e-3" ixy="0.0" ixz="0.0" iyy="1e-3" iyz="0.0" izz="1e-3"/>
      <mass value=".1"/>
    </inertial>
  </link>

  <link name="back_cover">
    <visual>
      <geometry>
        <box size=".01 .42 .41"/>
      </geometry>
      <material name="orange">
        <color rgba="1. .55 0. .8"/>
      </material>
    </visual>
    <collision>
      <geometry>
        <box size=".01 .42 .41"/>
      </geometry>
    </collision>
    <inertial>
      <inertia ixx="1e-3" ixy="0.0" ixz="0.0" iyy="1e-3" iyz="0.0" izz="1e-3"/>
      <mass value=".1"/>
    </inertial>
  </link>

  <link name="top_cover">
    <visual>
      <geometry>
        <box size=".39 .42 .01"/>
      </geometry>
      <material name="orange">
        <color rgba="1. .55 0. .8"/>
      </material>
    </visual>
    <collision>
      <geometry>
        <box size=".39 .42 .01"/>
      </geometry>
    </collision>
    <inertial>
      <inertia ixx="1e-3" ixy="0.0" ixz="0.0" iyy="1e-3" iyz="0.0" izz="1e-3"/>
      <mass value=".1"/>
    </inertial>
  </link>

  <joint name="top_cover_to_kinect_base" type="fixed">
    <parent link="top_cover"/>
    <child link="kinect_base"/>
    <origin xyz="0.16 0 0.015"/>
  </joint>

  <link name="kinect_base">
    <visual>
      <geometry>
        <box size=".07 .08 .02"/>
      </geometry>
      <material name="black">
        <color rgba="0.05 0.05 0.05 1"/>
      </material>
    </visual>
    <collision>
      <geometry>
        <box size=".07 .08 .02"/>
      </geometry>
    </collision>
    <inertial>
      <inertia ixx="1e-3" ixy="0.0" ixz="0.0" iyy="1e-3" iyz="0.0" izz="1e-3"/>
      <mass value=".1"/>
    </inertial>
  </link>

  <joint name="kinect_base_to_kinect_neck" type="fixed">
    <parent link="kinect_base"/>
    <child link="kinect_neck"/>
    <origin xyz="0 0 0.03"/>
  </joint>

  <link name="kinect_neck">
    <visual>
      <geometry>
        <cylinder length="0.04" radius="0.01" />
      </geometry>
      <material name="black">
        <color rgba="0.05 0.05 0.05 1"/>
      </material>
    </visual>
    <collision>
      <geometry>
        <cylinder length="0.04" radius="0.01" />
      </geometry>
    </collision>
    <inertial>
      <inertia ixx="1e-3" ixy="0.0" ixz="0.0" iyy="1e-3" iyz="0.0" izz="1e-3"/>
      <mass value=".1"/>
    </inertial>
  </link>

  <joint name="kinect_neck_to_kinect_sensor" type="fixed">
    <parent link="kinect_neck"/>
    <child link="kinect_sensor"/>
    <origin xyz="0 0 0.035" rpy="0 0.5236 0" />
  </joint>

  <link name="kinect_sensor">
    <visual>
      <geometry>
        <box size=".06 .28 .03"/>
      </geometry>
      <material name="black">
        <color rgba="0.05 0.05 0.05 1"/>
      </material>
    </visual>
    <collision>
      <geometry>
        <box size=".06 .28 .03"/>
      </geometry>
    </collision>
    <inertial>
      <inertia ixx="1e-3" ixy="0.0" ixz="0.0" iyy="1e-3" iyz="0.0" izz="1e-3"/>
      <mass value=".1"/>
    </inertial>
  </link>




  <joint name="base_link_to_base_arm" type="fixed">
    <parent link="base_link"/>
    <child link="base_arm"/>
    <origin xyz="0.215 0 0.615"/>
  </joint>


  <!-- Front Right Wheel -->
  <link name="f_r_wheel">
    <visual>
      <origin xyz="0 0 0" rpy="1.570795 0 0" />
      <geometry>
          <cylinder length="0.05" radius="0.05666" />
      </geometry>
      <material name="black">
        <color rgba="0.05 0.05 0.05 1"/>
      </material>
    </visual>
  </link>

  <joint name="joint_f_r_wheel" type="continuous">
    <parent link="base_link"/>
    <child link="f_r_wheel"/>
    <origin xyz="0.125 -0.15 0" rpy="0 0 0" /> 
    <axis xyz="0 1 0" rpy="0 0 0" />
  </joint>  

  <!-- Back Right Wheel -->
  <link name="b_r_wheel">
    <visual>
      <origin xyz="0 0 0" rpy="1.570795 0 0" />
      <geometry>
          <cylinder length="0.05" radius="0.05666" />
      </geometry>
      <material name="black"/>
    </visual>
  </link>

  <joint name="joint_b_r_wheel" type="continuous">
    <parent link="base_link"/>
    <child link="b_r_wheel"/>
    <origin xyz="-0.125 -0.15 0" rpy="0 0 0" /> 
    <axis xyz="0 1 0" rpy="0 0 0" />
  </joint>  
  <!-- Front Left Wheel -->

  <link name="f_l_wheel">
    <visual>
      <origin xyz="0 0 0" rpy="1.570795 0 0" />
      <geometry>
          <cylinder length="0.05" radius="0.05666" />
      </geometry>
      <material name="black"/>
    </visual>
  </link>

  <joint name="joint_f_l_wheel" type="continuous">
    <parent link="base_link"/>
    <child link="f_l_wheel"/>
    <origin xyz="0.125 0.15 0" rpy="0 0 0" /> 
    <axis xyz="0 1 0" rpy="0 0 0" />
  </joint>

  <!-- Back Left Wheel -->
  <link name="b_l_wheel">
    <visual>
      <origin xyz="0 0 0" rpy="1.570795 0 0" />
      <geometry>
          <cylinder length="0.05" radius="0.05666" />
      </geometry>
      <material name="black"/>
    </visual>
  </link>

  <joint name="joint_b_l_wheel" type="continuous">
    <parent link="base_link"/>
    <child link="b_l_wheel"/>
    <origin xyz="-0.125 0.15 0" rpy="0 0 0" /> 
    <axis xyz="0 1 0" rpy="0 0 0" />
  </joint>

  <link name="base_arm">
    <visual>
      <geometry>
        <cylinder length="0.09" radius="0.15"/>
      </geometry>
      <material name="blue">
        <color rgba="0 0 .8 1"/>
      </material>
    </visual>
    <collision>
      <geometry>
        <cylinder length="0.09" radius="0.15"/>
      </geometry>
    </collision>
    <inertial>
      <mass value="0.1"/>
      <inertia ixx="1e-3" ixy="0.0" ixz="0.0" iyy="1e-3" iyz="0.0" izz="1e-3"/>
    </inertial>
    <link_properties mu="0.0" kp="0.0" kd="0.1"/>
  </link>

  <joint name="base_arm_to_base2" type="revolute">
    <axis xyz="0 0 1"/>
    <parent link="base_arm"/>
    <child link="base2"/>
    <origin xyz="0 0 0"/>
    <limit effort="1000.0" lower="-2.70526" upper="2.70526" velocity="0.5"/>
  </joint>

  <link name="base2">
    <visual>
      <geometry>
        <cylinder length="0.09" radius="0.03"/>
      </geometry>
      <material name="blue">
      </material>
    </visual>
    <collision>
      <geometry>
        <cylinder length="0.09" radius="0.03"/>
      </geometry>
    </collision>
    <inertial>
      <mass value="0.1"/>
      <inertia ixx="1e-3" ixy="0.0" ixz="0.0" iyy="1e-3" iyz="0.0" izz="1e-3"/>
    </inertial>
    <link_properties mu="0.0" kp="0.0" kd="0.1"/>
  </link>

  <joint name="base_to_shoulder" type="revolute">
    <axis xyz="0 1 0"/>
    <parent link="base2"/>
    <child link="shoulder"/>
    <origin xyz="0 0 0.128"/>
    <limit effort="1000.0" lower="-1.57080" upper="1.57080" velocity="0.5"/>
  </joint>

  <link name="shoulder">
    <visual>
      <geometry>
        <box size="0.051 0.045 0.151"/>
      </geometry>
      <origin rpy="0 0 0" xyz="0 0 0.0495"/>
      <material name="white">
        <color rgba="1 1 1 1"/>
      </material>
    </visual>
    <collision>
      <geometry>
        <box size="0.051 0.045 0.151"/>
      </geometry>
      <origin rpy="0 0 0" xyz="0 0 0.0595"/>
    </collision>
    <inertial>
      <mass value="0.1"/>
      <inertia ixx="1e-3" ixy="0.0" ixz="0.0" iyy="1e-3" iyz="0.0" izz="1e-3"/>
    </inertial>
    <link_properties mu="0.0" kp="0.0" kd="0.1"/>
  </link>

  <joint name="shoulder_to_elbow" type="revolute">
    <axis xyz="0 -1 0"/>
    <parent link="shoulder"/>
    <child link="elbow"/>
    <origin rpy="0 0.17453 0" xyz="0.053 0 0.141"/>
    <limit effort="1000.0" lower="-1.57080" upper="1.57080" velocity="0.5"/>
  </joint>

  <link name="elbow">
    <visual>
      <geometry>
        <box size="0.1002 0.057 0.037"/>
# Original:       "0.167 0.057 0.037"         (O esboco foi adaptado para que nao houvesse superposicao de pecas)
      </geometry>
      <origin rpy="0 0 0" xyz="0.0441 0 0"/>
# Original:                   "0.0735 0 0" 
      <material name="blue">
      </material>
    </visual>
    <collision>
      <geometry>
        <box size="0.1002 0.057 0.037"/>
      </geometry>
      <origin rpy="0 0 0" xyz="0.0735 0 0"/>
    </collision>
    <inertial>
      <mass value="0.1"/>
      <inertia ixx="1e-3" ixy="0.0" ixz="0.0" iyy="1e-3" iyz="0.0" izz="1e-3"/>
    </inertial>
  </link>

  <joint name="elbow_to_wrist" type="revolute">
    <axis xyz="0 -1 0"/>
    <parent link="elbow"/>
    <child link="wrist"/>
    <origin rpy="0 0 0" xyz="0.144 0 0"/>
    <limit effort="1000.0" lower="-1.57080" upper="1.57080" velocity="0.5"/>
  </joint>

  <link name="wrist">
    <visual>
      <geometry>
        <box size="0.085 0.057 0.05"/>
      </geometry>
      <origin rpy="0 0 0" xyz="0.0325 0 -0.0065"/>
      <material name="white">
      </material>
    </visual>
    <collision>
      <geometry>
        <box size="0.085 0.057 0.05"/>
      </geometry>
      <origin rpy="0 0 0" xyz="0.0325 0 -0.0065"/>
    </collision>
    <inertial>
      <mass value="0.05"/>
      <inertia ixx="1e-3" ixy="0.0" ixz="0.0" iyy="1e-3" iyz="0.0" izz="1e-3"/>
    </inertial>
  </link>

  <joint name="wrist_to_grip_base" type="revolute">
    <axis xyz="1 0 0"/>
    <parent link="wrist"/>
    <child link="grip_base"/>
    <origin rpy="0 0 0" xyz="0.085 0 0"/>
    <limit effort="1000.0" lower="-2.70526" upper="2.70526" velocity="0.5"/>
  </joint>

  <link name="grip_base">
    <visual>
      <geometry>
        <box size="0.043 0.057 0.05"/>
      </geometry>
      <origin rpy="0 0 0" xyz="0.0325 0 -0.0065"/>
      <material name="blue">
      </material>
    </visual>
    <collision>
      <geometry>
        <box size="0.043 0.057 0.05"/>
      </geometry>
      <origin rpy="0 0 0" xyz="0.0325 0 -0.0065"/>
    </collision>
    <inertial>
      <mass value="0.05"/>
      <inertia ixx="1e-3" ixy="0.0" ixz="0.0" iyy="1e-3" iyz="0.0" izz="1e-3"/>
    </inertial>
  </link>
  
  <joint name="grip_base_to_right_finger" type="prismatic">
    <axis xyz="0 -1 0"/>
    <parent link="grip_base"/>
    <child link="right_finger"/>
    <origin rpy="0 0 0" xyz="0.0432 -0.017 0"/>
    <limit effort="1000.0" lower="-0.012" upper="0.012" velocity="0.5"/>
  </joint>

  <link name="right_finger">
    <visual>
      <geometry>
        <box size="0.0451 0.010 0.0283"/>
      </geometry>
      <origin rpy="0 0 0" xyz="0.02255 0 0"/>
      <material name="white">
      </material>
    </visual>
    <collision>
      <geometry>
        <box size="0.0451 0.010 0.0283"/>
      </geometry>
      <origin rpy="0 0 0" xyz="0.02255 0 0"/>
    </collision>
    <inertial>
      <mass value="0.01"/>
      <inertia ixx="1e-4" ixy="0.0" ixz="0.0" iyy="1e-4" iyz="0.0" izz="1e-4"/>
    </inertial>
  </link>

  <joint name="grip_base_to_left_finger" type="prismatic">
    <axis xyz="0 1 0"/>
    <parent link="grip_base"/>
    <child link="left_finger"/>
    <origin rpy="0 0 0" xyz="0.0432 0.017 0"/>
    <limit effort="1000.0" lower="-0.012" upper="0.012" velocity="0.5"/>
    <mimic joint="grip_base_to_right_finger" multiplier="1.0" offset="0.0" />
  </joint>

  <link name="left_finger">
    <visual>
      <geometry>
        <box size="0.0451 0.010 0.0283"/>
      </geometry>
      <origin rpy="0 0 0" xyz="0.02255 0 0"/>
      <material name="white">
      </material>
    </visual>
    <collision>
      <geometry>
        <box size="0.0451 0.010 0.0283"/>
      </geometry>
      <origin rpy="0 0 0" xyz="0.02255 0 0"/>
    </collision>
    <inertial>
      <mass value="0.01"/>
      <inertia ixx="1e-4" ixy="0.0" ixz="0.0" iyy="1e-4" iyz="0.0" izz="1e-4"/>
    </inertial>
  </link>

</robot>



